<?xml version="1.0"?>
<!-- xacro for rg2 mounted on the manipulator -->

<robot name="rg2" xmlns:xacro="http://ros.org/wiki/xacro">
  <xacro:macro name="rg2" params="prefix">

    <!--link name="gripper_extender_link" />

    <joint name="rg2_joint" type="fixed">
      <origin rpy="0 -1.57 0" xyz="0 0 0"/>
      <parent link="${prefix}gripper_extender_link"/>
      <child link="${prefix}rg2_body_link"/>
    </joint-->
    <link name="${prefix}rg2_body_link">

      <visual>
        <origin rpy="0 1.57 0" xyz="0.051 0.0085 0.0015"/>
        <geometry>
          <mesh filename="package://UR3e_RG2_ER5_description/meshes/rg2_gripper/dae_rg2_.dae" scale="0.001 0.001 0.001"/>
        </geometry>
        <material name="White">
          <color rgba="1.0 1.0 1.0 1.0"/>
        </material>
      </visual>


      <collision>
        <origin rpy="0 1.57 0" xyz="0.1 0.0 0.0"/>
        <geometry>
          <cylinder length="0.1" radius="0.05"/>
        </geometry>
      </collision>

      <inertial>
        <mass value="1"/>
        <inertia ixx="1" ixy="0.0" ixz="0.0" iyy="1" iyz="0.0" izz="1"/>
      </inertial>
    </link>

    <!--joint name="rg2_eef_joint" type="fixed">
      <origin rpy="0 0 0" xyz="0.195 0.0 0.0"/>
      <parent link="rg2_body_link"/>
      <child link="rg2_eef_link"/>
    </joint>
    <link name="rg2_eef_link"/-->

    <joint name="gripper_joint" type="revolute">
      <origin rpy="0 0 0" xyz="0.195 0.0 0.0"/>
      <axis  xyz="0 0 1" />
      <limit effort="1000" lower="0" upper="3.14" velocity="3.14"/>
      <parent link="rg2_body_link"/>
      <child link="rg2_eef_link"/>

    </joint>

    <link name="rg2_eef_link">
    <inertial>
        <mass value="1"/>
        <inertia ixx="1" ixy="0.0" ixz="0.0" iyy="1" iyz="0.0" izz="1"/>
      </inertial>
    </link>

    <transmission name="gripper_joint_trans">
      <type>transmission_interface/SimpleTransmission</type>
      <joint name="gripper_joint">
        <hardwareInterface>hardware_interface/PositionJointInterface</hardwareInterface>
      </joint>
      <actuator name="gripper_joint_motor">
        <mechanicalReduction>1</mechanicalReduction>
      </actuator>
    </transmission>

  </xacro:macro>
</robot>
